<?xml version="1.0"?>
<robot name="KR60">
	<link name="base_link" />
	<link name ="KR60Arm_link0">
		<visual>
			<geometry>
				<box size = "0.970000 0.05 0.05"/>
			</geometry>
			<origin xyz="0.000000 0.000000 -0.485000" rpy="0.00 -1.57 0.00" />
		</visual>
	</link>
	<link name ="KR60Arm_link1">
		<visual>
			<geometry>
				<box size = "0.410000 0.05 0.05"/>
			</geometry>
			<origin xyz="0.205000 0.000000 0.000000" rpy="0.00 0.00 0.00" />
		</visual>
	</link>
	<link name ="KR60Arm_link2">
		<visual>
			<geometry>
				<box size = "1.010000 0.05 0.05"/>
			</geometry>
			<origin xyz="0.505000 0.000001 0.000402" rpy="0.00 0.00 0.00" />
		</visual>
	</link>
	<link name ="KR60Arm_link3">
		<visual>
			<geometry>
				<box size = "0.619839 0.05 0.05"/>
			</geometry>
			<origin xyz="0.295074 0.094765 0.000780" rpy="0.00 0.00 0.31" />
		</visual>
	</link>
	<link name ="KR60Arm_link4">
		<visual>
			<geometry>
				<box size = "0.350571 0.05 0.05"/>
			</geometry>
			<origin xyz="-0.000519 0.009861 0.175007" rpy="0.00 1.57 1.62" />
		</visual>
	</link>
	<link name ="KR60Arm_link5">
		<visual>
			<geometry>
				<box size = "0.000000 0.05 0.05"/>
			</geometry>
			<origin xyz="0.000000 0.000000 0.000000" rpy="0.00 1.57 0.00" />
		</visual>
	</link>
	<link name="KR60Arm_link6">
		<visual>
			<geometry>
				<box size = "0.000000 0.05 0.05"/>
			</geometry>
			<origin xyz="0.000000 0 0" rpy="0.00 0.00 0.00" />
		</visual>
	</link>
	<joint name="base_joint" type="fixed">
		<parent link="base_link" />
		<child link="KR60Arm_link0" />
	</joint>
	<joint name="Joint_1" type="revolute">
		<parent link="KR60Arm_link0"/>
		<child link="KR60Arm_link1"/>
		<origin xyz="0.00 0.00 -0.97" rpy="3.14 -0.00 0.00" />
		<axis xyz="0.0 0.0 1" />
		<limit effort="600.000000" lower="-3.288000" upper="3.288000" velocity="0.5" />
	</joint>

	<joint name="Joint_2" type="revolute">
		<parent link="KR60Arm_link1"/>
		<child link="KR60Arm_link2"/>
		<origin xyz="0.41 0.00 0.00" rpy="-3.14 -1.57 -1.57" />
		<axis xyz="0.0 0.0 1" />
		<limit effort="1500.000000" lower="-0.610000" upper="2.356000" velocity="0.5" />
	</joint>

	<joint name="Joint_3" type="revolute">
		<parent link="KR60Arm_link2"/>
		<child link="KR60Arm_link3"/>
		<origin xyz="1.01 0.00 0.00" rpy="0.00 0.00 -1.57" />
		<axis xyz="0.0 0.0 1" />
		<limit effort="700.000000" lower="-2.757000" upper="2.094000" velocity="0.5" />
	</joint>

	<joint name="Joint_4" type="revolute">
		<parent link="KR60Arm_link3"/>
		<child link="KR60Arm_link4"/>
		<origin xyz="0.59 0.19 0.00" rpy="2.36 1.57 2.36" />
		<axis xyz="0.0 0.0 1" />
		<limit effort="100.000000" lower="-6.108000" upper="6.108000" velocity="0.5" />
	</joint>

	<joint name="Joint_5" type="revolute">
		<parent link="KR60Arm_link4"/>
		<child link="KR60Arm_link5"/>
		<origin xyz="-0.00 0.02 0.35" rpy="-0.79 -1.57 -2.36" />
		<axis xyz="0.0 0.0 1" />
		<limit effort="60.000000" lower="-2.076000" upper="2.076000" velocity="0.5" />
	</joint>

	<joint name="Joint_6" type="revolute">
		<parent link="KR60Arm_link5"/>
		<child link="KR60Arm_link6"/>
		<origin xyz="0.00 0.00 0.00" rpy="3.14 -1.57 -3.14" />
		<axis xyz="0.0 0.0 1" />
		<limit effort="25.000000" lower="-6.108000" upper="6.108000" velocity="0.5" />
	</joint>

</robot>
