<?xml version="1.0"?>
<robot name="KR60">
  <!-- materials for visualization -->
  <material name="White">
    <color rgba="1.0 1.0 1.0 1.0"/>
  </material>
  <material name="Black">
    <color rgba="0.1 0.1 0.1 1.0"/>
  </material>

  <link name="base_link" />

  <!-- Mesh Start -->
  <link name="KR60Arm_link0">
    <visual>
      <geometry>
	<mesh filename="package://usarsim_inf/urdf/meshes/kr60_1.dae"/>
      </geometry>
      <material name="White"/>
      <origin xyz="0. 0. 0" rpy="3.14 0 0." />
    </visual>
    <collision>
      <geometry>
	<box size = "0.80 0.05 0.05"/>
      </geometry>
      <origin xyz="0.06 0.01 -0.40" rpy="0.00 1.43 0.18" />
    </collision>
  </link>
  <!-- Mesh End -->

  <!-- Mesh Start -->
  <link name ="KR60Arm_link1">
    <visual>
      <geometry>
	<mesh filename="package://usarsim_inf/urdf/meshes/kr60_2.dae"/>
      </geometry>
      <material name="White"/>
      <!-- z joint offset - z of link2 in kr60Arm.uc -->
      <!-- <origin xyz="0.212 -0.008 -0.104" rpy="0 0 0." /> -->
      <origin xyz="0.212 0.024 -0.104" rpy="0 0 0." />
    </visual>
    <collision>
      <geometry>
	<box size = "1.01 0.05 0.05"/>
      </geometry>
      <origin xyz="0.50 0.00 0.00" rpy="0.00 -0.00 0.00" />
    </collision>
  </link>
  <!-- Mesh End -->

  <!-- Mesh Start -->
  <link name ="KR60Arm_link2">
    <visual>
      <geometry>
	<mesh filename="package://usarsim_inf/urdf/meshes/kr60_3.dae"/>
      </geometry>
      <material name="White"/>
      <!-- <origin xyz="-0.236 0.592 -0.008" rpy="0 0 0" /> -->
      <origin xyz="0.592 0.008   0.236" rpy="-1.571 0 -1.571" />
    </visual>
    <collision>
      <geometry>
	<box size = "1.01 0.05 0.05"/>
      </geometry>
      <origin xyz="0.50 0.00 0.00" rpy="0.00 -0.00 0.00" />
    </collision>
  </link>
  <!-- Mesh End -->

  <!-- Mesh Start -->
  <link name ="KR60Arm_link3">
    <visual>
      <geometry>
	<mesh filename="package://usarsim_inf/urdf/meshes/kr60_4.dae"/>
      </geometry>
      <origin xyz="0.088 0.108 0.020" rpy="-1.571 0 0" />
	<!-- <origin xyz="-0.236 0.592 -0.008" rpy="0 0 0" /> -->
    </visual>
    <collision>
      <geometry>
	<box size = "0.62 0.05 0.05"/>
      </geometry>
      <origin xyz="0.30 0.09 0.00" rpy="0.00 -0.00 0.31" />
    </collision>
  </link>
  <!-- Mesh End -->

  <!-- Mesh Start -->
  <link name ="KR60Arm_link4">
    <visual>
      <geometry>
	<mesh filename="package://usarsim_inf/urdf/meshes/kr60_5.dae"/>
      </geometry>
      <!--<material name="White"/> -->
      <origin xyz="-0.004 0.008 0.2" rpy="0 4.71 -1.571" />
	<!-- <origin xyz="-0.236 0.592 -0.008" rpy="0 0 0" /> -->
    </visual>
    <collision>
      <geometry>
	<box size = "0.35 0.05 0.05"/>
      </geometry>
      <origin xyz="-0.00 0.01 0.18" rpy="0.00 -1.57 1.62" />
    </collision>
  </link>
  <!-- Mesh End -->

  <!-- Mesh Start -->
  <link name ="KR60Arm_link5">
    <visual>
      <geometry>
	<mesh filename="package://usarsim_inf/urdf/meshes/kr60_6.dae"/>
      </geometry>
      <!--<material name="White"/> -->
      <origin xyz="0.06 0 0" rpy="-1.571 0 0" />
	<!-- <origin xyz="-0.236 0.592 -0.008" rpy="0 0 0" /> -->
    </visual>
    <collision>
      <geometry>
	<box size = "0.01 0.05 0.05"/>
      </geometry>
      <origin xyz="0.00 -0.00 0.00" rpy="0.00 -1.57 -1.30" />
    </collision>
  </link>
  <!-- Mesh End -->

  <!-- Mesh Start -->
  <link name ="KR60Arm_link6">
    <visual>
      <geometry>
	<mesh filename="package://usarsim_inf/urdf/meshes/kr60_7.dae"/>
      </geometry>
      <!--<material name="White"/> -->
      <origin xyz="0 0 -0.036" rpy="-1.57 1.57  0" />
    </visual>
    <collision>
      <geometry>
	<box size = "0.05 0.05 0.05"/>
      </geometry>
      <origin xyz="-0.00 0.00 -0.02" rpy="0.00 1.57 3.06" />
    </collision>
  </link>
  <!-- Mesh End -->


  <joint name="KR60Arm_mount" type="fixed">
    <parent link="base_link" />
    <child link="KR60Arm_link0" />
    <origin xyz="0.00 0.00 -0.00" rpy="0.00 -0.00 0.00" />
  </joint>

  <joint name="KR60Arm_joint_1" type="revolute">
    <parent link="KR60Arm_link0"/>
    <child link="KR60Arm_link1"/>
    <origin xyz="0.112 0.016 -0.792" rpy="3.14 -0.00 0.00" />
    <axis xyz="0.0 0.0 1" />
    <limit effort="600.00" lower="-3.14" upper="3.14" velocity="1.0" />
  </joint>

  <joint name="KR60Arm_joint_2" type="revolute">
    <parent link="KR60Arm_link1"/>
    <child link="KR60Arm_link2"/>
    <!-- <origin xyz="0.408 0 0" rpy="-4.7125 1.571 0" /> -->
    <origin xyz="0.408 0 0" rpy="-3.14 -1.57 -1.57" />
    <axis xyz="0.0 0.0 1" />
    <limit effort="1500.00" lower="-0.61" upper="2.36" velocity="1.0" />
  </joint>

  <joint name="KR60Arm_joint_3" type="revolute">
    <parent link="KR60Arm_link2"/>
    <child link="KR60Arm_link3"/>
    <!-- <origin xyz="0.408 0 0" rpy="-4.7125 1.571 0" /> -->
    <origin xyz="1.008 0 0" rpy="0.00 0.00 -1.57" />
    <axis xyz="0.0 0.0 1" />
    <limit effort="700.00" lower="-2.76" upper="2.09" velocity="1.0" />
  </joint>

 <joint name="KR60Arm_joint_4" type="revolute">
    <parent link="KR60Arm_link3"/>
    <child link="KR60Arm_link4"/>
    <!-- <origin xyz="0.408 0 0" rpy="-4.7125 1.571 0" /> -->
    <origin xyz="0.592 0.192 0" rpy="2.36 1.57 2.36" />
    <axis xyz="0.0 0.0 1" />
    <limit effort="100.00" lower="-3.14" upper="3.14" velocity="1.0" />
  </joint>

  <joint name="KR60Arm_joint_5" type="revolute">
    <parent link="KR60Arm_link4"/>
    <child link="KR60Arm_link5"/>
    <!-- <origin xyz="0.408 0 0" rpy="-4.7125 1.571 0" /> -->
    <origin xyz="-0 0.018 0.350" rpy="-0.79 -1.57 -2.36" />
    <axis xyz="0.0 0.0 1" />
    <limit effort="60.00" lower="-2.08" upper="2.08" velocity="1.0" />
  </joint>

  <joint name="KR60Arm_joint_6" type="revolute">
    <parent link="KR60Arm_link5"/>
    <child link="KR60Arm_link6"/>
    <!-- <origin xyz="0.408 0 0" rpy="-4.7125 1.571 0" /> -->
    <origin xyz="0.144 0 0.006" rpy="3.14 -1.57 -3.14" />
    <axis xyz="0.0 0.0 1" />
    <limit effort="25.00" lower="-3.14" upper="3.14" velocity="1.0" />
  </joint>
</robot>
