<?xml version="1.0"?>
<robot name="KR60">
	<link name="base_link" />
	<link name ="KR60Arm_link0">

	</link>
	<link name ="KR60Arm_link1">
		
	</link>
	<link name ="KR60Arm_link2">
		
	</link>
	<link name ="KR60Arm_link3">
		
	</link>
	<link name ="KR60Arm_link4">
		
	</link>
	<link name ="KR60Arm_link5">
		
	</link>
	<link name ="KR60Arm_link6">
		
	</link>
	<link name = "toolchange">
	</link>
	<joint name="KR60Arm_mount" type="fixed">
		<parent link="base_link" />
		<child link="KR60Arm_link0" />
		<origin xyz="0.000 0.000 0.000" rpy="0.000 -0.000 0.000" />
	</joint>
	<joint name="KR60Arm_joint_1" type="revolute">
		<parent link="KR60Arm_link0"/>
		<child link="KR60Arm_link1"/>
		<origin xyz="0.070 0.010 -0.413" rpy="-3.140 -0.000 0.000" />
		<axis xyz="0.000 0.000 1.000" />
		<limit effort="600.000" lower="-3.140" upper="3.140" velocity="1.0" />
	</joint>

	<joint name="KR60Arm_joint_2" type="revolute">
		<parent link="KR60Arm_link1"/>
		<child link="KR60Arm_link2"/>
		<origin xyz="0.424 0.211 0.383" rpy="-1.410 -1.570 2.980" />
		<axis xyz="0.000 0.000 1.000" />
		<limit effort="1500.000" lower="-2.356" upper="0.610" velocity="1.0" />
	</joint>

	<joint name="KR60Arm_joint_3" type="revolute">
		<parent link="KR60Arm_link2"/>
		<child link="KR60Arm_link3"/>
		<origin xyz="1.004 0.003 0.059" rpy="0.000 0.000 -1.570" />
		<axis xyz="0.000 0.000 1.000" />
		<limit effort="700.000" lower="-2.094" upper="2.757" velocity="1.0" />
	</joint>

	<joint name="KR60Arm_joint_4" type="revolute">
		<parent link="KR60Arm_link3"/>
		<child link="KR60Arm_link4"/>
		<origin xyz="0.491 0.168 0.161" rpy="2.360 1.570 2.360" />
		<axis xyz="0.000 0.000 1.000" />
		<limit effort="100.000" lower="-3.140" upper="3.140" velocity="1.0" />
	</joint>

	<joint name="KR60Arm_joint_5" type="revolute">
		<parent link="KR60Arm_link4"/>
		<child link="KR60Arm_link5"/>
		<origin xyz="-0.068 -0.001 0.492" rpy="-0.790 -1.570 -2.360" />
		<axis xyz="0.000 0.000 1.000" />
		<limit effort="60.000" lower="-2.076" upper="2.076" velocity="1.0" />
	</joint>

	<joint name="KR60Arm_joint_6" type="revolute">
		<parent link="KR60Arm_link5"/>
		<child link="KR60Arm_link6"/>
		<origin xyz="0.152 -0.000 0.070" rpy="3.140 -1.570 -3.140" />
		<axis xyz="0.000 0.000 1.000" />
		<limit effort="25.000" lower="-3.140" upper="3.140" velocity="1.0" />
	</joint>

	<joint name = "toolchange_mount" type = "fixed">
		<parent link = "KR60Arm_link6" />
		<child link = "toolchange" />
		<origin xyz = "0.000 0.000 -0.070" rpy = "-3.142 0.002 -1.577" />
	</joint>
</robot>
